tests/fixtures/binance_btcusdt_deltas.jsonl
{"e":"depthUpdate","E":1783157230714,"s":"BTCUSDT","U":96935779238,"u":96935779293,"b":[["62459.99000000","0.00883000"],["62458.05000000","0.00819000"],["62458.03000000","0.37421000"],["62458.01000000","0.48656000"],["62457.51000000","0.57471000"],["62455.01000000","0.57489000"],["62454.00000000","0.05665000"],["62453.90000000","0.00000000"],["62453.75000000","0.10019000"],["62335.12000000","0.00148000"],["56214.00000000","0.00683000"]],"a":[["62460.01000000","0.95601000"],["62460.02000000","0.00134000"],["62462.01000000","0.02525000"],["62463.25000000","0.00040000"],["62463.64000000","0.52898000"],["62465.01000000","0.14655000"],["62465.41000000","0.00000000"],["62465.90000000","0.15980000"],["62467.00000000","0.39013000"],["62467.01000000","0.15962000"],["62467.09000000","0.00000000"],["62467.99000000","0.00000000"],["62468.25000000","0.00000000"],["62469.21000000","0.38576000"],["62471.01000000","0.00000000"],["62471.67000000","0.38970000"],["62473.57000000","0.00000000"],["62475.01000000","0.00400000"]]}
{"e":"depthUpdate","E":1783157230814,"s":"BTCUSDT","U":96935779294,"u":96935779298,"b":[["62329.12000000","0.00000000"],["56214.00000000","0.00683000"]],"a":[]}
{"e":"depthUpdate","E":1783157230914,"s":"BTCUSDT","U":96935779299,"u":96935779315,"b":[["62460.00000000","3.11141000"],["61523.10000000","0.00030000"],["56214.00000000","0.00683000"]],"a":[["62460.01000000","0.76906000"],["62553.69000000","0.00011000"]]}
{"e":"depthUpdate","E":1783157231014,"s":"BTCUSDT","U":96935779316,"u":96935779335,"b":[["62460.00000000","3.39852000"],["62430.90000000","0.00000000"],["62240.00000000","3.00957000"],["62177.76000000","3.00000000"],["62115.52000000","3.00000000"],["56214.00000000","0.00703000"],["49968.00000000","0.00040000"]],"a":[["62530.55000000","1.72796000"],["62532.62000000","0.00000000"],["63396.92000000","0.00030000"]]}
{"e":"depthUpdate","E":1783157231114,"s":"BTCUSDT","U":96935779336,"u":96935779365,"b":[["62460.00000000","3.40671000"],["62458.05000000","0.85177000"],["62458.04000000","1.59994000"],["62458.03000000","0.00018000"],["62457.07000000","0.00033000"],["62453.75000000","0.10028000"],["62453.49000000","0.09118000"],["62452.72000000","0.07842000"],["62409.43000000","0.00000000"],["62407.44000000","0.00016000"],["56214.00000000","0.00713000"]],"a":[["62460.01000000","0.38920000"],["62460.73000000","0.00000000"],["62460.74000000","0.00027000"],["62463.25000000","0.00000000"],["62465.00000000","0.00009000"],["62471.67000000","0.18648000"],["62474.27000000","0.00000000"],["62475.06000000","0.60095000"],["62584.96000000","0.00011000"]]}
{"e":"depthUpdate","E":1783157231214,"s":"BTCUSDT","U":96935779366,"u":96935779393,"b":[["62459.90000000","0.00009000"],["62458.95000000","0.04009000"],["62458.05000000","0.85177000"],["62458.03000000","0.00000000"],["62453.64000000","0.00000000"],["62312.33000000","0.00000000"],["62311.59000000","0.01002000"],["56214.00000000","0.00713000"],["49968.00000000","0.00000000"]],"a":[["62460.01000000","0.38868000"],["62460.74000000","0.00009000"],["62461.43000000","0.00009000"],["62465.90000000","0.15998000"],["62466.91000000","0.00069000"]]}
{"e":"depthUpdate","E":1783157231314,"s":"BTCUSDT","U":96935779394,"u":96935779413,"b":[["62459.99000000","0.00883000"],["62458.96000000","0.00018000"],["62458.06000000","0.00018000"],["62458.05000000","0.85186000"],["62454.00000000","0.05656000"],["56214.00000000","0.00693000"]],"a":[["62460.01000000","0.38850000"],["62460.02000000","0.00125000"],["62461.23000000","0.08037000"],["62475.10000000","0.08836000"],["62477.10000000","0.00000000"]]}
{"e":"depthUpdate","E":1783157231414,"s":"BTCUSDT","U":96935779414,"u":96935779429,"b":[["56214.00000000","0.00693000"],["49968.00000000","0.00000000"]],"a":[["62460.01000000","0.38877000"],["62461.22000000","0.00018000"],["62461.95000000","0.01611000"],["62465.00000000","0.00000000"],["62465.90000000","0.15980000"],["62490.57000000","0.00000000"]]}
{"e":"depthUpdate","E":1783157231514,"s":"BTCUSDT","U":96935779430,"u":96935779456,"b":[["62455.48000000","0.00000000"],["62455.47000000","0.00091000"],["62454.00000000","0.05647000"],["62446.69000000","0.00000000"],["56214.00000000","0.00693000"]],"a":[["62460.01000000","0.38886000"],["62460.02000000","0.00143000"],["62461.22000000","0.00027000"],["62461.23000000","0.08055000"],["62461.94000000","0.00009000"],["62463.94000000","0.15979000"],["62465.01000000","0.14637000"],["62468.71000000","0.00081000"],["62468.72000000","0.00000000"],["62471.68000000","0.00000000"]]}
{"e":"depthUpdate","E":1783157231614,"s":"BTCUSDT","U":96935779457,"u":96935779464,"b":[["62446.69000000","0.00009000"],["56214.00000000","0.00693000"]],"a":[["62461.43000000","0.00000000"],["62461.65000000","0.00163000"],["62471.68000000","0.00009000"]]}
{"e":"depthUpdate","E":1783157231714,"s":"BTCUSDT","U":96935779465,"u":96935779471,"b":[["62290.76000000","0.09632000"],["56214.00000000","0.00713000"]],"a":[["62460.01000000","0.76569000"],["62593.33000000","0.09585000"]]}
{"e":"depthUpdate","E":1783157231814,"s":"BTCUSDT","U":96935779472,"u":96935779484,"b":[["62455.48000000","0.00081000"],["62455.47000000","0.00010000"],["56214.00000000","0.00713000"]],"a":[["62460.01000000","0.76638000"],["62466.91000000","0.00000000"],["62468.71000000","0.00000000"],["62468.72000000","0.00081000"],["62503.75000000","0.08000000"],["62505.30000000","0.00000000"],["68706.01000000","0.00009000"]]}
{"e":"depthUpdate","E":1783157231914,"s":"BTCUSDT","U":96935779485,"u":96935779499,"b":[["62460.00000000","3.41163000"],["62458.01000000","0.43656000"],["62455.48000000","0.00000000"],["62455.47000000","0.00091000"],["61523.10000000","0.00030000"],["56214.00000000","0.00713000"]],"a":[["62461.65000000","0.00009000"],["62468.71000000","0.00081000"],["62468.72000000","0.00000000"],["68706.01000000","0.00000000"]]}
{"e":"depthUpdate","E":1783157232014,"s":"BTCUSDT","U":96935779500,"u":96935779515,"b":[["62460.00000000","3.40352000"],["62458.97000000","0.00801000"],["62430.90000000","0.08000000"],["62429.35000000","0.70000000"],["56214.00000000","0.00693000"],["49968.00000000","0.00040000"]],"a":[["62460.01000000","0.76639000"],["63396.92000000","0.00030000"]]}
{"e":"depthUpdate","E":1783157232114,"s":"BTCUSDT","U":96935779516,"u":96935779555,"b":[["62460.00000000","3.40134000"],["62459.99000000","0.00883000"],["62458.97000000","0.00819000"],["62458.95000000","0.04027000"],["62458.02000000","0.07551000"],["62457.69000000","0.05011000"],["62455.48000000","0.00000000"],["62455.47000000","0.00091000"],["56214.00000000","0.00683000"],["56213.99000000","0.00010000"]],"a":[["62460.01000000","0.76612000"],["62461.94000000","0.00018000"],["62461.95000000","0.01629000"],["62468.71000000","0.00081000"],["62468.72000000","0.00000000"],["62472.50000000","0.00322000"],["62472.51000000","0.00000000"],["62503.75000000","0.78000000"]]}
{"e":"depthUpdate","E":1783157232214,"s":"BTCUSDT","U":96935779556,"u":96935779567,"b":[["60055.00000000","0.01665000"],["56214.00000000","0.00683000"],["49968.00000000","0.00000000"]],"a":[["62463.93000000","0.00000000"],["62463.94000000","0.00027000"]]}
{"e":"depthUpdate","E":1783157232314,"s":"BTCUSDT","U":96935779568,"u":96935779597,"b":[["62460.00000000","3.41544000"],["62455.48000000","0.00000000"],["62455.47000000","0.00091000"],["62312.33000000","0.01002000"],["62311.59000000","0.00000000"],["62290.76000000","0.00000000"],["56214.00000000","0.00683000"]],"a":[["62460.01000000","0.76603000"],["62460.02000000","0.00134000"],["62463.64000000","0.52898000"],["62463.94000000","0.00009000"],["62465.01000000","0.14655000"],["62468.71000000","0.00081000"],["62468.72000000","0.00000000"],["62472.50000000","0.00000000"],["62472.51000000","0.00320000"],["62593.33000000","0.00000000"]]}
{"e":"depthUpdate","E":1783157232414,"s":"BTCUSDT","U":96935779598,"u":96935779609,"b":[["56214.00000000","0.00703000"],["49968.00000000","0.00000000"]],"a":[["62460.01000000","0.38929000"]]}
