tests/fixtures/coinbase_btcusd.jsonl
{"type": "snapshot", "product_id": "BTC-USD", "asks": [["62399.14", "0.01569901"], ["62401.14", "0.00010016"], ["62401.64", "0.00811277"], ["62402.00", "0.04890000"], ["62402.26", "0.00801253"], ["62402.66", "0.12819967"], ["62403.54", "0.15865791"], ["62403.88", "0.00001800"], ["62404.00", "0.04890000"], ["62405.00", "0.01000000"], ["62406.00", "0.04660000"], ["62406.15", "0.16024064"], ["62406.25", "0.04817408"], ["62406.26", "0.18817989"], ["62406.47", "0.00009700"], ["62406.64", "0.00485000"], ["62406.96", "0.00001800"], ["62407.14", "0.09585928"], ["62408.00", "0.04660000"], ["62408.37", "0.04890000"], ["62409.29", "0.00160096"], ["62409.34", "0.03201777"], ["62409.35", "0.09585928"], ["62409.52", "0.00019400"], ["62409.80", "0.00970000"], ["62409.99", "0.14837629"], ["62410.00", "0.05660000"], ["62410.04", "0.00001800"], ["62411.98", "0.00800365"], ["62411.99", "0.09585928"], ["62412.00", "0.04660000"], ["62412.03", "0.00099578"], ["62412.04", "0.00028936"], ["62413.12", "0.00001800"], ["62413.26", "0.04817408"], ["62413.49", "0.10964063"], ["62414.00", "0.04660000"], ["62414.31", "0.04743227"], ["62415.00", "0.01000000"], ["62415.06", "0.09585928"]], "bids": [["62399.13", "0.27721413"], ["62398.82", "0.03958685"], ["62398.81", "0.19585612"], ["62398.31", "0.00185269"], ["62398.27", "0.04817408"], ["62398.04", "0.09585928"], ["62397.26", "0.12821075"], ["62397.19", "0.00160259"], ["62396.72", "0.16023341"], ["62396.31", "0.00801329"], ["62396.25", "0.00160259"], ["62396.12", "0.12821308"], ["62396.00", "0.04890000"], ["62395.69", "0.00801337"], ["62395.32", "0.09585928"], ["62395.24", "0.00035133"], ["62394.64", "0.00001800"], ["62394.45", "0.00240387"], ["62394.00", "0.04890000"], ["62393.28", "0.20701099"], ["62393.27", "0.09585928"], ["62393.25", "0.04817408"], ["62393.15", "0.02819900"], ["62392.01", "0.04002142"], ["62392.00", "0.04660000"], ["62391.56", "0.00004266"], ["62390.80", "0.09585928"], ["62390.29", "0.17228232"], ["62390.00", "0.04660000"], ["62388.92", "0.09666057"], ["62388.48", "0.00001800"], ["62388.44", "0.03886773"], ["62388.13", "0.00300484"], ["62388.02", "0.04817408"], ["62387.50", "0.67158867"], ["62386.89", "0.03201777"], ["62386.77", "0.00029209"], ["62386.71", "0.09585928"], ["62386.12", "0.00344664"], ["62385.76", "0.00583000"]], "time": "2026-07-04T09:27:19.164377Z"}
{"type":"l2update","product_id":"BTC-USD","changes":[["sell","65540.05","0.00007629"],["sell","62436.21","0.00000000"]],"time":"2026-07-04T09:27:19.164377Z"}
{"type":"l2update","product_id":"BTC-USD","changes":[["buy","54599.24","0.00000000"],["sell","62591.75","0.00000000"]],"time":"2026-07-04T09:27:19.233116Z"}
{"type":"l2update","product_id":"BTC-USD","changes":[["buy","62391.77","0.06042550"],["sell","62401.14","0.04459037"],["sell","62483.07","0.01061683"]],"time":"2026-07-04T09:27:19.294395Z"}
{"type":"l2update","product_id":"BTC-USD","changes":[["buy","62396.32","0.00801329"],["buy","62373.24","0.00110407"],["sell","62401.64","0.01612538"],["sell","62401.14","0.04479069"]],"time":"2026-07-04T09:27:19.357572Z"}
{"type":"l2update","product_id":"BTC-USD","changes":[["buy","54599.24","0.01396680"],["sell","62590.52","0.00139950"],["sell","62795.08","0.00000000"]],"time":"2026-07-04T09:27:19.400471Z"}
{"type":"l2update","product_id":"BTC-USD","changes":[["buy","62391.77","0.00000000"],["buy","49919.30","0.00020000"]],"time":"2026-07-04T09:27:19.477567Z"}
{"type":"l2update","product_id":"BTC-USD","changes":[["buy","54599.24","0.00000000"],["buy","62395.70","0.00400669"],["sell","62494.43","0.00000000"],["sell","62402.26","0.01201880"],["sell","62401.64","0.01617546"]],"time":"2026-07-04T09:27:19.511115Z"}
{"type":"l2update","product_id":"BTC-USD","changes":[["buy","62398.51","0.02670536"]],"time":"2026-07-04T09:27:19.562622Z"}
{"type":"l2update","product_id":"BTC-USD","changes":[["buy","62357.76","0.00000000"],["buy","62357.78","0.97134466"],["buy","62396.32","0.01602658"],["buy","62396.31","0.00000000"],["buy","62357.77","0.00000000"],["buy","62340.44","0.83764001"],["sell","62401.64","0.01617546"],["sell","62429.55","0.00000000"],["sell","62401.14","0.04479069"],["sell","62429.56","0.00000000"],["sell","62429.54","0.62885863"]],"time":"2026-07-04T09:27:19.640524Z"}
{"type":"l2update","product_id":"BTC-USD","changes":[["buy","54599.24","0.01396680"]],"time":"2026-07-04T09:27:19.699621Z"}
{"type":"l2update","product_id":"BTC-USD","changes":[["buy","62398.51","0.00000000"],["buy","49919.30","0.00000000"],["sell","62436.21","0.02155239"],["sell","62487.63","0.09206423"]],"time":"2026-07-04T09:27:19.745062Z"}
{"type":"l2update","product_id":"BTC-USD","changes":[["buy","54599.24","0.00000000"]],"time":"2026-07-04T09:27:19.798555Z"}
