tests/fixtures/kraken_btcusd_book.jsonl
{"channel":"book","type":"snapshot","data":[{"symbol":"BTC/USD","bids":[{"price":62622.3,"qty":0.00923841},{"price":62621.9,"qty":0.79844203},{"price":62621.6,"qty":0.00005100},{"price":62619.9,"qty":0.00176642},{"price":62619.8,"qty":0.03190752},{"price":62619.6,"qty":0.79847082},{"price":62618.5,"qty":0.00005100},{"price":62616.3,"qty":0.26660465},{"price":62616.2,"qty":0.81909689},{"price":62615.3,"qty":0.00005100}],"asks":[{"price":62622.9,"qty":0.03654491},{"price":62623.4,"qty":0.08068898},{"price":62623.5,"qty":0.36550540},{"price":62624.6,"qty":0.00005100},{"price":62626.5,"qty":0.03190752},{"price":62626.6,"qty":0.00126608},{"price":62626.8,"qty":0.05020883},{"price":62627.0,"qty":0.19021714},{"price":62627.1,"qty":0.15968426},{"price":62627.5,"qty":0.79426830}],"checksum":814493173,"timestamp":"2026-07-05T10:37:38.932102Z"}]}
{"channel":"book","type":"update","data":[{"symbol":"BTC/USD","bids":[],"asks":[{"price":62623.4,"qty":0.07892262},{"price":62626.4,"qty":0.00176636}],"checksum":643939250,"timestamp":"2026-07-05T10:37:39.090964Z"}]}
{"channel":"book","type":"update","data":[{"symbol":"BTC/USD","bids":[{"price":62619.8,"qty":0.00000000},{"price":62612.3,"qty":0.01300000},{"price":62620.0,"qty":0.03190752}],"asks":[],"checksum":1152716144,"timestamp":"2026-07-05T10:37:39.092410Z"}]}
{"channel":"book","type":"update","data":[{"symbol":"BTC/USD","bids":[],"asks":[{"price":62626.5,"qty":0.00000000},{"price":62627.5,"qty":0.79426830},{"price":62626.3,"qty":0.03190752}],"checksum":948617565,"timestamp":"2026-07-05T10:37:39.092568Z"}]}
{"channel":"book","type":"update","data":[{"symbol":"BTC/USD","bids":[{"price":62619.9,"qty":0.00000000},{"price":62612.3,"qty":0.01300000},{"price":62619.7,"qty":0.00176643}],"asks":[],"checksum":3844822255,"timestamp":"2026-07-05T10:37:39.093757Z"}]}
{"channel":"book","type":"update","data":[{"symbol":"BTC/USD","bids":[],"asks":[{"price":62626.4,"qty":0.00000000},{"price":62627.5,"qty":0.79426830},{"price":62626.2,"qty":0.00176636}],"checksum":1134347882,"timestamp":"2026-07-05T10:37:39.094008Z"}]}
{"channel":"book","type":"update","data":[{"symbol":"BTC/USD","bids":[{"price":62620.0,"qty":0.00000000},{"price":62612.3,"qty":0.01300000},{"price":62619.8,"qty":0.03190752}],"asks":[],"checksum":1705197912,"timestamp":"2026-07-05T10:37:39.095125Z"}]}
{"channel":"book","type":"update","data":[{"symbol":"BTC/USD","bids":[{"price":62619.7,"qty":0.00000000},{"price":62612.3,"qty":0.01300000},{"price":62619.9,"qty":0.00176642}],"asks":[],"checksum":4243186970,"timestamp":"2026-07-05T10:37:39.096621Z"}]}
{"channel":"book","type":"update","data":[{"symbol":"BTC/USD","bids":[{"price":62619.8,"qty":0.00000000},{"price":62612.3,"qty":0.01300000},{"price":62620.0,"qty":0.03190752}],"asks":[],"checksum":2654819288,"timestamp":"2026-07-05T10:37:39.393456Z"}]}
{"channel":"book","type":"update","data":[{"symbol":"BTC/USD","bids":[],"asks":[{"price":62626.3,"qty":0.00000000},{"price":62627.5,"qty":0.79426830},{"price":62626.1,"qty":0.03190752}],"checksum":3779333760,"timestamp":"2026-07-05T10:37:39.393482Z"}]}
{"channel":"book","type":"update","data":[{"symbol":"BTC/USD","bids":[{"price":62619.9,"qty":0.00000000},{"price":62612.3,"qty":0.01300000},{"price":62619.7,"qty":0.00176643}],"asks":[],"checksum":1021680434,"timestamp":"2026-07-05T10:37:39.395457Z"}]}
